I'm sorry, but an uncaught exception occurred.

While running game code:
  File "game/script.rpy", line 19, in script call
    call cardgame1 from _call_cardgame1
  File "game/cardgame.rpy", line 758, in script
    python:
  File "game/cardgame.rpy", line 760, in <module>
    i.artificial()
  File "game/cardgame.rpy", line 446, in artificial
    self.battle_cards_a(number)
  File "game/cardgame.rpy", line 459, in battle_cards_a
    self.handle_battle(i)
  File "game/cardgame.rpy", line 485, in handle_battle
    b_list = locals()[f'b{opponent.position}']
KeyError: 'b3'

-- Full Traceback ------------------------------------------------------------

Full traceback:
  File "game/script.rpy", line 19, in script call
    call cardgame1 from _call_cardgame1
  File "game/cardgame.rpy", line 758, in script
    python:
  File "E:\Downloads 2\renpy-8.0.0-sdk\renpy\ast.py", line 1138, in execute
    renpy.python.py_exec_bytecode(self.code.bytecode, self.hide, store=self.store)
  File "E:\Downloads 2\renpy-8.0.0-sdk\renpy\python.py", line 1122, in py_exec_bytecode
    exec(bytecode, globals, locals)
  File "game/cardgame.rpy", line 760, in <module>
    i.artificial()
  File "game/cardgame.rpy", line 446, in artificial
    self.battle_cards_a(number)
  File "game/cardgame.rpy", line 459, in battle_cards_a
    self.handle_battle(i)
  File "game/cardgame.rpy", line 485, in handle_battle
    b_list = locals()[f'b{opponent.position}']
KeyError: 'b3'

Windows-10-10.0.22621 AMD64
Ren'Py 8.1.3.23091805
Triple Triad 1.0
Wed Jan  3 10:54:42 2024
