I'm sorry, but an uncaught exception occurred.

While running game code:
  File "game/script.rpy", line 17, in script call
    call cardgame1 from _call_cardgame1
  File "game/cardgame.rpy", line 667, in script
    python:
  File "game/cardgame.rpy", line 670, in <module>
    board[x - 1].append(allies[0])
IndexError: list index out of range

-- Full Traceback ------------------------------------------------------------

Full traceback:
  File "game/script.rpy", line 17, in script call
    call cardgame1 from _call_cardgame1
  File "game/cardgame.rpy", line 667, in script
    python:
  File "E:\Downloads 2\renpy-7.3.5-sdk\renpy\ast.py", line 914, in execute
    renpy.python.py_exec_bytecode(self.code.bytecode, self.hide, store=self.store)
  File "E:\Downloads 2\renpy-7.3.5-sdk\renpy\python.py", line 2028, in py_exec_bytecode
    exec bytecode in globals, locals
  File "game/cardgame.rpy", line 670, in <module>
    board[x - 1].append(allies[0])
  File "E:\Downloads 2\renpy-7.3.5-sdk\renpy\python.py", line 847, in __getitem__
    rv = list.__getitem__(self, index)
IndexError: list index out of range

Windows-8-6.2.9200
Ren'Py 7.3.5.606
Triple Triad 1.0
Sat Oct 31 20:30:54 2020
